---
title: "Exercises Chapter 8"
author: "Semiramis Castro-Jaimes"
date: "30/6/2020"
output: html_document
---

Predict the results of evaluating the following code

```{r}
show_condition <- function(code) {
  tryCatch(
    error = function(cnd) "error",
    warning = function(cnd) "warning",
    message = function(cnd) "message",
    {
      code
      NULL
    }
  )
}

show_condition(stop("!"))
show_condition(10)
show_condition(warning("?!"))
show_condition({
  10
  message("?")
  warning("?!")
})

```
## Answer:
- case A) will print "error"
- case B) will print "NULL"
- case C) will print "warning"
- case D will terminate when we arrive to the message. Remember: exiting handlers are called in the context of tryCatch()


Explain the results of running this code:
```{r}
withCallingHandlers(
  message = function(cnd) message("b"),
  withCallingHandlers(
    message = function(cnd) message("a"),
    message("c")
  )
)

```
## Answer:
- First, we enter into (1): the message is "b"
- then, we go to (2): the message is "a"
- we return to (1) because we didn't handle the message "b", so it bubbles up to the outer calling handler
- finally, we go to "c"


Compare the following two implementations of message2error(). What is the main advantage of withCallingHandlers() in this scenario? (Hint: look carefully at the traceback.)
```{r}
message2error_withCallingHandlers <- function(code) {
  withCallingHandlers(code, message = function(e) stop(e))
}
message2error_withCallingHandlers( {1; 
  message("hidden error"); NULL} )
traceback()
```

```{r}
message2error_tryCatch <- function(code) {
  tryCatch(code, message = function(e) stop(e))
}
message2error_tryCatch({1; 
  message("hidden error"); NULL} )
traceback()
```
## Answer:
withCallingHandlers() returns more information and points us to the exact call in our code because it is called in the context of the call that signalled the condition, whereas exiting handlers are called in the context of tryCatch()


Why is catching interrupts dangerous? Run this code to find out.
```{r eval=FALSE}
bottles_of_beer <- function(i = 99) {
  message(
    "There are ", i, " bottles of beer on the wall, ", 
    i, " bottles of beer."
  )
  while(i > 0) {
    tryCatch(
      Sys.sleep(1),
      interrupt = function(err) {
        i <<- i - 1
        if (i > 0) {
          message(
            "Take one down, pass it around, ", i, 
            " bottle", if (i > 1) "s", " of beer on the wall."
          )
        }
      }
    )
  }
  message(
    "No more bottles of beer on the wall, ", 
    "no more bottles of beer."
  )
}
```
## Answer:
If we run that code, we won't be able to stop it unless we kill the process from our terminal

